Workbook

Sheet Logistics record 
A1: Move HK route from Starlink to UHAN's fwd | AC1: Tỷ giá | AD1: 26462
A2: UHAN Payment in Month | D2: 45658 | E2: 45689 | F2: 45717 | G2: 45748 | H2: 45778 | I2: 45809 | J2: 45839 | K2: 45870 | L2: 45901 | M2: 45931 | N2: 45962 | O2: 45992 | P2: 46023 | Q2: 46054 | R2: 46082 | S2: 46113 | T2: 46143 | U2: 46174
B3: Full logistics cost (Unigen pay) | D3: =D5-D4 -> 26480.584 | E3: =E5-E4 -> 26132.98 | F3: =F5-F4 -> 33641.018 | G3: =G5-G4 -> 33015.803 | H3: =H5-H4 -> 38983.797 | I3: =I5-I4 -> 44867.902 | J3: =J5-J4 -> 42915.709 | K3: =K5-K4 -> 62058.689 | ... N3: =N5-N4 -> 92101.001 | O3: 79951.99 | P3: 56495.208 | Q3: 40169.203 | R3: 35311.391 | S3: 31992.676 | T3: 34640.775 | U3: =U5-U4 -> 35866.719 | W3: Detail of raising: (SUM) | X3: Tracking/INV | Y3: Consignee/Shipper | Z3: =SUM(Z4:Z9) -> 385.45839
C4: Pay on behalf of others | D4: 4048.6692 | E4: 3024.6214 | F4: 7479.8127 | G4: 5886.7599 | H4: 11929.093 | I4: 2570.6327 | J4: 6520.1634 | K4: 2458.2838 | L4: 12377.15 | M4: 3933.3031 | N4: 3960.316 | O4: 8568.3017 | P4: 1696.0434 | Q4: 1329.7689 | R4: 4516.8992 | S4: 675.60553 | T4: 2752.5485 | U4: =Z13 -> 9194.6792 | W4: RMA | X4: INV06879 | Y4: MATAN DIGITAL PRINTERS 2001 LTD. | Z4: 15.116015
A5: Total Logistics cost (include pay on behalf of others) | D5: =SUM(D17+D50+D51+D52) -> 30529.253 | E5: =SUM(E17+E50+E51+E52) -> 29157.602 | F5: =SUM(F17+F50+F51+F52) -> 41120.831 | G5: =G17+G50+G51+G52 -> 38902.563 | H5: 50912.89 | I5: =I17+I50+I51+I52 -> 47438.535 | J5: =J17+J50+J51+J52 -> 49435.872 | K5: =K17+K50+K51+K52 -> 64516.973 | L5: =L17+L50+L51+L52 -> 79469.818 | M5: =M17+M50+M51+M52 -> 74219.52 | N5: =N17+N50+N51+N52 -> 96061.317 | O5: 88520.292 | P5: 58191.252 | Q5: 41498.972 | R5: 39828.291 | S5: 32668.282 | T5: 37393.323 | U5: =U17+U50+U51+U52 -> 45061.398 | W5: RMA | X5: INV06857 | Y5: Lucid USA, Inc.(CasaGrande Whse) | Z5: 15.116015
A6: Import | B6: Raw materials (Supplier to UHAN) | C6: Freight | D6: 15426.511 | E6: 20289.672 | F6: 23089.23 | G6: 26743.123 | H6: 30140.19 | I6: 27086.524 | J6: 30923.757 | K6: 42036.32 | L6: 47441.34 | M6: =45665.6558113536-546.52 -> 45119.136 | N6: 62891.245 | O6: 56967.015 | P6: 43467.765 | Q6: 27352.373 | R6: 26797.207 | S6: 22861.48 | T6: 21430.89 | U6: ='Debit Summary'!A6+'Debit Summary'!B6+'Debit Summary'!C6+'Debit Summary'!D6+'Debit Summary'!E6+'Debit Summary'!G6 -> 23157.228 | W6: RMA | X6: INV06840 | Y6: HELLA GmbH & Co. KGaA. | Z6: 15.116015
C7: Shipment No# | D7: ='Import material detail'!D2+'Import material detail'!D5+'Import material detail'!D11 -> 91 | E7: ='Import material detail'!E2+'Import material detail'!E5+'Import material detail'!E11 -> 119 | F7: ='Import material detail'!F2+'Import material detail'!F5+'Import material detail'!F11 -> 146 | G7: ='Import material detail'!G2+'Import material detail'!G5+'Import material detail'!G11 -> 153 | H7: 161 | I7: ='Import material detail'!I2+'Import material detail'!I5+'Import material detail'!I11 -> 197 | J7: ='Import material detail'!J2+'Import material detail'!J5+'Import material detail'!J11 -> 146 | K7: 240 | L7: 237 | M7: 262 | N7: ='Import material detail'!N2+'Import material detail'!N5+'Import material detail'!N11 -> 269 | O7: 263 | P7: 207 | Q7: 196 | R7: 156 | S7: 149 | T7: 112 | U7: ='Debit Summary'!A7+'Debit Summary'!B7+'Debit Summary'!C7+'Debit Summary'!D7+'Debit Summary'!E7+'Debit Summary'!G7 -> 171 | W7: Handle customs for wrong weight shipment | X7: INV06819 | Y7: AIC | Z7: =9000000/AD1 -> 340.11035
C8: Weight of Freight (KG) | D8: 10154.65 | E8: 14337.72 | F8: 12048.42 | G8: 18644.4 | H8: 25191.46 | I8: 21137.97 | J8: 25034.7 | K8: 40755.74 | L8: 37897.265 | M8: 45142.48 | N8: 47706.056 | O8: 55349.783 | P8: 35083.926 | Q8: 23788.92 | R8: 10237.445 | S8: 16565.673 | T8: 18241.364 | U8: =SUM('Debit Summary'!A8:G8) -> 15681.871 | W8: MRO Machine | X8: x | Y8: x | Z8: x
C9: Customs & Trucking fees | D9: =6907.35+451.2 -> 7358.55 | E9: =6595+144 -> 6739 | F9: 7641.0108 | G9: =7844.32+370.31 -> 8214.63 | H9: 9479.21 | I9: 10714.885 | J9: 11863.437 | K9: 15520.52 | L9: 18187.94 | M9: 20964.916 | N9: 19021.774 | O9: 17365.977 | P9: 10119.204 | Q9: 8249.5262 | R9: 7376.2303 | S9: 6542.1566 | T9: 9359.5515 | U9: ='Debit Summary'!A9+'Debit Summary'!B9+'Debit Summary'!C9+'Debit Summary'!D9+'Debit Summary'!E9+'Debit Summary'!G9 -> 17704.253
C10: Import declaration No# | D10: ='Import material detail'!D14 -> 251 | E10: ='Import material detail'!E14 -> 251 | F10: ='Import material detail'!F14 -> 290 | G10: ='Import material detail'!G14 -> 333 | H10: ='Import material detail'!H14 -> 312 | I10: ='Import material detail'!I14 -> 438 | J10: ='Import material detail'!J14 -> 515 | K10: ='Import material detail'!K14 -> 578 | L10: 596 | M10: 781 | N10: 788 | O10: 635 | P10: 381 | Q10: 331 | R10: 358 | S10: 289 | T10: 336 | U10: ='Debit Summary'!A10+'Debit Summary'!B10+'Debit Summary'!C10+'Debit Summary'!D10+'Debit Summary'!E10+'Debit Summary'!G10 -> 531
C11: Subtotal of Raw materials | D11: =D9+D6 -> 22785.061 | E11: =E9+E6 -> 27028.672 | F11: =F9+F6 -> 30730.24 | G11: =G9+G6 -> 34957.753 | H11: 39619.4 | I11: =I9+I6 -> 37801.409 | J11: =J9+J6 -> 42787.194 | K11: =K9+K6 -> 57556.84 | L11: =L9+L6 -> 65629.28 | M11: =M9+M6 -> 66084.052 | N11: =N9+N6 -> 81913.019 | O11: 74332.993 | P11: 53586.969 | Q11: 35601.9 | R11: 34173.438 | S11: 29403.637 | T11: 30790.442 | U11: =U9+U6 -> 40861.481
B12: Equipments + Toolings | C12: Freight | D12: 2740.032 | E12: 0 | F12: 2795.6731 | G12: 0 | H12: $ - | I12: 2112.75 | J12: 872.82 | K12: 1749.41 | L12: 6713.3374 | M12: 1061.9926 | N12: 5487.0877 | O12: 1293.5894 | P12: 86.048164 | Q12: 0 | R12: 13.906384 | S12: 544.54526 | T12: 1675.7718 | U12: ='Debit Summary'!A12+'Debit Summary'!B12+'Debit Summary'!C12+'Debit Summary'!D12+'Debit Summary'!E12+'Debit Summary'!G12 -> 669.35217 | Z12: Cost | AA12: Quote customer
C13: Weight of Freight (KG) | D13: 4220 KG | E13: 0 KG | F13: 3318 KG | G13: 0 | H13: $ - | I13: 5185 | J13: 1020 | K13: 4260 | L13: 14564 | M13: 383 | N13: 13995 | O13: 1293.5894 | P13: 0 | Q13: 0 | R13: 0 | S13: 82 | T13: 3959 | U13: =SUM('Debit Summary'!A13:G13) -> 288 | W13: UHAN pay on behalf of Others (SUM) | X13: Tracking/INV | Y13: Consignee/Shipper | Z13: =SUM(Z14:Z133) -> 9194.6792 | AA13: =SUM(AA14:AA133) -> 12000
C14: Customs & Trucking fees | D14: =240+1279.16 -> 1519.16 | E14: 132 | F14: 2523.0517 | G14: =244.835501147666+527.81+15.3 -> 787.9455 | H14: 752.28 | I14: 1779.4605 | J14: 408.9116 | K14: 1428.29 | L14: 895.02967 | M14: 1264.71 | N14: 2960.5659 | O14: 1801.4838 | P14: 887.50503 | Q14: 563.72795 | R14: 587.94503 | S14: 600.85229 | T14: 1743.3324 | U14: ='Debit Summary'!A14+'Debit Summary'!B14+'Debit Summary'!C14+'Debit Summary'!D14+'Debit Summary'!E14+'Debit Summary'!G14 -> 608.41933 | W14: PURE | X14: 8XN5256 | Y14: KIOXIA CORPORATION C/O KIOXIA AMERICA INC | Z14: 75.866526 | AA14: 100 | AB14: Victoria charge $100 to customer
C15: Subtotal of Equipments & Toolings | D15: =SUM(D12:D14) -> 4259.192 | E15: =SUM(E12:E14) -> 132 | F15: =SUM(F12:F14) -> 5318.7248 | G15: =SUM(G12:G14) -> 787.9455 | H15: 752.28 | I15: =I14+I12 -> 3892.2105 | J15: =J14+J12 -> 1281.7316 | K15: =K14+K12 -> 3177.7 | L15: =L14+L12 -> 7608.3671 | M15: =M14+M12 -> 2326.7026 | N15: =N14+N12 -> 8447.6537 | O15: 3095.0732 | P15: 973.5532 | Q15: 563.72795 | R15: 601.85141 | S15: 1145.3976 | T15: 3419.1043 | U15: =U14+U12 -> 1277.7715 | W15: PURE | X15: 8XN5262 | Y15: KIOXIA CORPORATION C/O KIOXIA AMERICA INC | Z15: 75.866526 | AA15: 100 | AB15: Victoria charge $100 to customer
C16: Other freight charges | F16: 2320 | H16: 819.98 | I16: 1880 | K16: 565.04 | L16: 1175.6229 | N16: 965.57992 | U16: =22000000/AD1 -> 831.38085 | W16: PURE | X16: 8XN5254 | Y16: KIOXIA CORPORATION C/O KIOXIA AMERICA INC | Z16: 75.866526 | AA16: 100 | AB16: Victoria charge $100 to customer
B17: Subtotal | D17: =D11+D15+D16 -> 27044.253 | E17: =E11+E15+E16 -> 27160.672 | F17: =F11+F15+F16 -> 38368.965 | G17: =G11+G15+G16 -> 35745.699 | H17: =H11+H15+H16 -> 41191.66 | I17: =I11+I15+I16 -> 43573.62 | J17: =J11+J15+J16 -> 44068.925 | K17: =K11+K15+K16 -> 61299.58 | ... N17: =N11+N15+N16 -> 91326.253 | O17: 77428.066 | P17: 54560.522 | Q17: 36165.628 | R17: 34775.289 | S17: 30549.034 | T17: 34209.546 | U17: =U11+U15+U16 -> 42970.633 | W17: PURE | X17: 8XN5259 | Y17: KIOXIA CORPORATION C/O KIOXIA AMERICA INC | Z17: 75.866526 | AA17: 100 | AB17: Victoria charge $100 to customer
A18: Export | B18: Transfer to HQ1, MY | C18: Freight | D18: 1742 | E18: 400.37184 | F18: 353.8289 | G18: 157.56094 | H18: 221.76339 | I18: 402.85 | J18: =737.03+2202.92 -> 2939.95 | K18: 308.84042 | L18: 1888.9864 | M18: 2401.1 | N18: =1219.9066716305-35.12 -> 1184.7867 | O18: 4463.5949 | P18: 475.29078 | Q18: 129.64758 | R18: 330.67037 | S18: 253.60432 | T18: 1156.3564 | U18: ='Debit Summary'!A18+'Debit Summary'!B18+'Debit Summary'!C18+'Debit Summary'!D18+'Debit Summary'!E18+'Debit Summary'!G18 -> 354.56802 | W18: PURE | X18: 8XN5270 | Y18: KIOXIA CORPORATION C/O KIOXIA AMERICA INC | Z18: 75.866526 | AA18: 100 | AB18: Victoria charge $100 to customer
C19: Weight of Freight | D19: 184.2 KG | E19: 53.9 KG | F19: 39.5 KG | G19: 10.2 KG | H19: 15.3 KG | I19: 44.5 KG | J19: 330 | K19: 22.2 | L19: 281.8 KG | M19: 379.9 | N19: 103.2 | O19: 1225.9 | P19: 41.4 | Q19: 8.4 | R19: 34.3 | S19: 21.1 | T19: 121 | U19: =SUM('Debit Summary'!A19:G19) -> 27 | W19: PURE | X19: 8XN5255 | Y19: KIOXIA CORPORATION C/O KIOXIA AMERICA INC | Z19: 75.866526 | AA19: 100 | AB19: Victoria charge $100 to customer
C20: Customs & Trucking fees | D20: =4190000/25000 -> 167.6 | E20: =2180000/25000 -> 87.2 | F20: 208.71914 | G20: =2410000/26140 -> 92.195868 | H20: 234.17239 | I20: 82.83 | J20: 201.89394 | K20: 130.33 | L20: =1930000/26369 -> 73.192006 | M20: =4110000/26388 -> 155.75261 | N20: 264.68249 | O20: 181.57695 | P20: 136.18975 | Q20: 221.23389 | R20: 193.07363 | S20: 193.04434 | T20: 140.50901 | U20: ='Debit Summary'!A20+'Debit Summary'!B20+'Debit Summary'!C20+'Debit Summary'!D20+'Debit Summary'!E20+'Debit Summary'!G20 -> 239.96674 | W20: PURE | X20: 8XN5912 | Y20: KIOXIA CORPORATION C/O KIOXIA AMERICA INC | Z20: 75.866526 | AA20: 100 | AB20: Victoria charge $100 to customer
C21: Subtotal of Transfer Raw Materials | D21: =SUM(D18:D20) -> 1909.6 | E21: =SUM(E18:E20) -> 487.57184 | F21: =SUM(F18:F20) -> 562.54803 | G21: =SUM(G18:G20) -> 249.75681 | H21: =SUM(H18:H20) -> 455.93577 | I21: =I20+I18 -> 485.68 | J21: =J20+J18 -> 3141.8439 | K21: =K20+K18 -> 439.17042 | L21: =L20+L18 -> 1962.1784 | M21: =M20+M18 -> 2556.8527 | N21: =N20+N18 -> 1449.4692 | O21: 4645.1718 | P21: 611.48053 | Q21: 350.88148 | R21: 523.744 | S21: 446.64865 | T21: 1296.8654 | U21: =U20+U18 -> 594.53477 | W21: PURE | X21: 8XN5273 | Y21: KIOXIA CORPORATION C/O KIOXIA AMERICA INC | Z21: 75.866526 | AA21: 100 | AB21: Victoria charge $100 to customer
B22: LUCID | C22: Freight | D22: 101 | E22: 58.71316 | F22: 81.018519 | G22: 0 | H22: 8129.72 | I22: 0 | J22: 50.73467 | K22: 0 | L22: 0 | M22: 0 | N22: 0 | O22: 1755.0862 | P22: 28.417521 | Q22: 28.724408 | R22: 1974.1019 | S22: 22.441992 | T22: 0 | U22: ='Debit Summary'!A22+'Debit Summary'!B22+'Debit Summary'!C22+'Debit Summary'!D22+'Debit Summary'!E22+'Debit Summary'!G22 -> 0 | W22: PURE | X22: 8XN5266 | Y22: KIOXIA CORPORATION C/O KIOXIA AMERICA INC | Z22: 75.866526 | AA22: 100 | AB22: Victoria charge $100 to customer
C23: Weight of Freight | D23: 5.8 KG | E23: 3.6 KG | F23: 21.7 KG | G23: 0 | H23: 1138 KG | I23: 0 KG | J23: 0.6 | K23: 0 | L23: 0 | M23: 0 | N23: 0 | O23: 2.7 | P23: 1.1 | Q23: 0.8 | R23: 249.6 | S23: 0.3 | T23: 0 | U23: =SUM('Debit Summary'!A23:G23) -> 0 | W23: PURE | X23: 8XN5252 | Y23: KIOXIA CORPORATION C/O KIOXIA AMERICA INC | Z23: 75.866526 | AA23: 100 | AB23: Victoria charge $100 to customer
C24: Customs & Trucking fees | D24: =2000000/25000 -> 80 | E24: =7890000/25000 -> 315.6 | F24: 136.18827 | G24: =3200000/26140 -> 122.41775 | H24: 195.65217 | I24: 121.58 | J24: 203.78788 | K24: 210.95 | L24: =(19130000+700000)/26369 -> 752.01942 | M24: =18108000/26388 -> 686.22101 | N24: =1179.50202582453+339.74 -> 1519.242 | O24: 794.94428 | P24: 622.55761 | Q24: 508.60988 | R24: 529.1507 | S24: 383.43384 | T24: 285.18406 | U24: ='Debit Summary'!A24+'Debit Summary'!B24+'Debit Summary'!C24+'Debit Summary'!D24+'Debit Summary'!E24+'Debit Summary'!G24 -> 211.62422 | W24: PURE | X24: 8XN5275 | Y24: KIOXIA CORPORATION C/O KIOXIA AMERICA INC | Z24: 75.866526 | AA24: 100 | AB24: Victoria charge $100 to customer
C25: Subtotal of FG Lucid | D25: =SUM(D22:D24) -> 181 | E25: =SUM(E22:E24) -> 374.31316 | F25: =SUM(F22:F24) -> 217.20679 | G25: =SUM(G22:G24) -> 122.41775 | H25: =SUM(H22:H24) -> 8325.3722 | I25: =I24+I22 -> 121.58 | J25: =J24+J22 -> 254.52255 | K25: =K24+K22 -> 210.95 | L25: =L24+L22 -> 752.01942 | M25: =M24+M22 -> 686.22101 | N25: =N24+N22 -> 1519.242 | O25: 2550.0305 | P25: 650.97513 | Q25: 537.33428 | R25: 2503.2526 | S25: 405.87583 | T25: 285.18406 | U25: =U24+U22 -> 211.62422 | W25: PURE | X25: 8XN5253 | Y25: KIOXIA CORPORATION C/O KIOXIA AMERICA INC | Z25: 75.866526 | AA25: 100 | AB25: Victoria charge $100 to customer
B26: AGIGA | C26: Freight | D26: 82 | E26: 210.99108 | F26: 198.15988 | G26: 88 | H26: 77.493631 | I26: 0 | J26: 0 | K26: 52.3 | L26: 0 | M26: 0 | N26: 0 | O26: 0 | P26: 0 | Q26: 0 | R26: 0 | S26: 0 | T26: 0 | U26: ='Debit Summary'!A26+'Debit Summary'!B26+'Debit Summary'!C26+'Debit Summary'!D26+'Debit Summary'!E26+'Debit Summary'!G26 -> 0 | W26: PURE | X26: 8XN5264 | Y26: KIOXIA CORPORATION C/O KIOXIA AMERICA INC | Z26: 75.866526 | AA26: 100 | AB26: Victoria charge $100 to customer
C27: Weight of Freight | D27: 7.8 KG | E27: 16.4 KG | F27: 15.6 KG | G27: 4.6 KG | H27: 11.6 KG | I27: 0 KG | J27: 0 | K27: 2.4 | L27: 0 | M27: 0 | N27: 0 | U27: =SUM('Debit Summary'!A27:G27) -> 0 | W27: PURE | X27: 8XN5258 | Y27: KIOXIA CORPORATION C/O KIOXIA AMERICA INC | Z27: 75.866526 | AA27: 100 | AB27: Victoria charge $100 to customer
C28: Customs & Trucking fees | D28: =3450000/25000 -> 138 | E28: =1930000/25000 -> 77.2 | F28: 74.459877 | G28: =1930000/26140 -> 73.833206 | H28: 24.790236 | I28: 15.2 | J28: 0 | K28: 24.484876 | L28: move to OEM | M28: move to OEM | N28: move to OEM | O28: move to OEM | P28: move to OEM | Q28: move to OEM | R28: move to OEM | S28: move to OEM | T28: move to OEM | U28: move to OEM | W28: PURE | X28: 8XN5257 | Y28: KIOXIA CORPORATION C/O KIOXIA AMERICA INC | Z28: 75.866526 | AA28: 100 | AB28: Victoria charge $100 to customer
C29: Subtotal of FG AGIGA | D29: =SUM(D26:D28) -> 220 | E29: =SUM(E26:E28) -> 288.19108 | F29: =SUM(F26:F28) -> 272.61975 | G29: =SUM(G26:G28) -> 161.83321 | H29: =SUM(H26:H28) -> 102.28387 | I29: =SUM(I26:I28) -> 15.2 | J29: =SUM(J26:J28) -> 0 | K29: =SUM(K26:K28) -> 79.184876 | ... N29: =SUM(N26:N28) -> 0 | O29: 0 | P29: 0 | Q29: 0 | R29: 0 | S29: 0 | T29: 0 | U29: =SUM(U26:U28) -> 0 | W29: PURE | X29: 8XN5268 | Y29: KIOXIA CORPORATION C/O KIOXIA AMERICA INC | Z29: 75.866526 | AA29: 100 | AB29: Victoria charge $100 to customer
B30: EFI | C30: Freight | D30: 0 | E30: 0 | F30: 228.65328 | G30: 0 | H30: 0 | I30: =109.42+1540.17 -> 1649.59 | J30: =103.64+391.75 -> 495.39 | K30: 772.93 | L30: 0 | M30: 0 | O30: 0 | P30: 873.91243 | Q30: 72.426008 | R30: 0 | S30: 0 | T30: 0 | U30: ='Debit Summary'!A30+'Debit Summary'!B30+'Debit Summary'!C30+'Debit Summary'!D30+'Debit Summary'!E30+'Debit Summary'!G30 -> 0 | W30: PURE | X30: 8XN5271 | Y30: KIOXIA CORPORATION C/O KIOXIA AMERICA INC | Z30: 75.866526 | AA30: 100 | AB30: Victoria charge $100 to customer
C31: Weight of Freight | D31: 0 | E31: 0 | F31: 27.3 KG | I31: 196.9 KG | J31: 9.2 | K31: 61.5 | L31: 0 | M31: 0 | O31: 0 | P31: 93 | Q31: 4.9 | R31: 0 | S31: 0 | T31: 0 | U31: =SUM('Debit Summary'!A31:G31) -> 0 | W31: PURE | X31: 8XN5272 | Y31: KIOXIA CORPORATION C/O KIOXIA AMERICA INC | Z31: 75.866526 | AA31: 100 | AB31: Victoria charge $100 to customer
C32: Customs fees & Trucking for Inspection by Customs | D32: =2400000/25000+45.2 -> 141.2 | E32: =800000/25000 -> 32 | F32: 114.96914 | G32: =400000/26140 -> 15.302219 | H32: 201.373 | I32: 60.79 | J32: 204.92424 | K32: 87.77 | L32: =400000/26369 -> 15.169328 | M32: =800000/26388 -> 30.316811 | N32: 60.585406 | O32: 233.51024 | P32: 119.73986 | Q32: 39.913331 | R32: 0 | S32: 58.027079 | T32: 15.14922 | U32: ='Debit Summary'!A32+'Debit Summary'!B32+'Debit Summary'!C32+'Debit Summary'!D32+'Debit Summary'!E32+'Debit Summary'!G32 -> 90.696093 | W32: PURE | X32: 8XN5904 | Y32: KIOXIA CORPORATION C/O KIOXIA AMERICA INC | Z32: 75.866526 | AA32: 100 | AB32: Victoria charge $100 to customer
C33: Fees paid to EFI's fwd (term FOB) | D33: 0 | E33: 0 | F33: 0 | G33: 0 | H33: 0 | I33: 0 | J33: 0 | K33: 0 | L33: 0 | M33: 0 | W33: PURE | X33: 8XN5907 | Y33: KIOXIA CORPORATION C/O KIOXIA AMERICA INC | Z33: 75.866526 | AA33: 100 | AB33: Victoria charge $100 to customer
C34: Subtotal of EFI | D34: =D30+D32+D33 -> 141.2 | E34: =E30+E32+E33 -> 32 | F34: =F30+F32+F33 -> 343.62242 | G34: =G30+G32+G33 -> 15.302219 | H34: =H30+H32+H33 -> 201.373 | I34: =I30+I32+I33 -> 1710.38 | J34: =J30+J32+J33 -> 700.31424 | K34: =K30+K32+K33 -> 860.7 | ... N34: =N30+N32+N33 -> 60.585406 | O34: 233.51024 | P34: 993.6523 | Q34: 112.33934 | R34: 0 | S34: 58.027079 | T34: 15.14922 | U34: =U30+U32+U33 -> 90.696093 | W34: PURE | X34: 8XN5906 | Y34: KIOXIA CORPORATION C/O KIOXIA AMERICA INC | Z34: 75.866526 | AA34: 100 | AB34: Victoria charge $100 to customer
B35: PURE | C35: Freight (For RMA shipment) | F35: 165.89506 | G35: 311 | H35: 45.995767 | I35: 280.18 | J35: 272.2551 | K35: 179.99376 | L35: 198.88331 | M35: =10240094/26388 -> 388.05874 | N35: 83.395927 | O35: 43.756825 | P35: 62.842464 | Q35: 69.856198 | R35: 687.23237 | S35: 61.328213 | T35: 302.52233 | U35: ='Debit Summary'!A35+'Debit Summary'!B35+'Debit Summary'!C35+'Debit Summary'!D35+'Debit Summary'!E35+'Debit Summary'!G35 -> 79.008767 | W35: PURE | X35: 8XN5267 | Y35: KIOXIA CORPORATION C/O KIOXIA AMERICA INC | Z35: 75.866526 | AA35: 100 | AB35: Victoria charge $100 to customer
C36: Weight of Freight | F36: 20 KG | G36: 34 KG | H36: 11.2 KG | I36: 28.8 KG | J36: 22.1 | K36: 13 | L36: 14.6 KG | M36: 33.5 | N36: 6.2 | O36: 2.2 | P36: 12.4 | Q36: 2 | R36: 2.8 | S36: 3 | T36: 10.6 | U36: =SUM('Debit Summary'!A36:G36) -> 2.3 | W36: PURE | X36: 8XN5263 | Y36: KIOXIA CORPORATION C/O KIOXIA AMERICA INC | Z36: 75.866526 | AA36: 100 | AB36: Victoria charge $100 to customer
C37: Customs fees & Trucking for Inspection by Customs | D37: =2000000/25000 -> 80 | E37: =3130000/25000 -> 125.2 | F37: 717.20679 | G37: =3800000/26140 -> 145.37108 | H37: 83.142639 | I37: 272.42 | J37: =271.59+60 -> 331.59 | K37: 499.11 | L37: =18280000/26369 -> 693.23827 | M37: =9160000/26388 -> 347.12748 | N37: 343.06486 | O37: 383.62396 | P37: 257.45983 | Q37: 237.95948 | R37: 480.21849 | S37: 478.62859 | T37: 627.55643 | U37: ='Debit Summary'!A37+'Debit Summary'!B37+'Debit Summary'!C37+'Debit Summary'!D37+'Debit Summary'!E37+'Debit Summary'!G37 -> 213.51372 | W37: PURE | X37: 8XN5265 | Y37: KIOXIA CORPORATION C/O KIOXIA AMERICA INC | Z37: 75.866526 | AA37: 100 | AB37: Victoria charge $100 to customer
C38: Subtotal of FG Pure | D38: =D35+D37 -> 80 | E38: =E35+E37 -> 125.2 | F38: =F35+F37 -> 883.10185 | G38: =G35+G37 -> 456.37108 | H38: =H35+H37 -> 129.13841 | I38: =I35+I37 -> 552.6 | J38: =J35+J37 -> 603.8451 | K38: =K35+K37 -> 679.10376 | ... N38: =N35+N37 -> 426.46079 | O38: 427.38078 | P38: 320.3023 | Q38: 307.81568 | R38: 1167.4509 | S38: 539.9568 | T38: 930.07876 | U38: =U35+U37 -> 292.52249 | W38: PURE | X38: 8XN5910 | Y38: KIOXIA CORPORATION C/O KIOXIA AMERICA INC | Z38: 75.866526 | AA38: 100 | AB38: Victoria charge $100 to customer
B39: AIC | C39: Freight | E39: 63.89112 | F39: 0 | G39: 0 | H39: 0 | I39: 0 | J39: 0 | K39: 0 | L39: 0 | M39: =2105236/26388 -> 79.780052 | N39: 0 | O39: 0 | P39: 0 | Q39: 0 | R39: 0 | S39: 0 | T39: 0 | U39: ='Debit Summary'!A39+'Debit Summary'!B39+'Debit Summary'!C39+'Debit Summary'!D39+'Debit Summary'!E39+'Debit Summary'!G39 -> 0 | W39: PURE | X39: 8XN5274 | Y39: KIOXIA CORPORATION C/O KIOXIA AMERICA INC | Z39: 75.866526 | AA39: 100 | AB39: Victoria charge $100 to customer
C40: Weight of Freight | E40: 16.5 KG | F40: 0 KG | G40: 0 KG | H40: 0 KG | I40: 0 KG | J40: 0 | K40: 0 | L40: 0 | M40: 10.1 | N40: 0 | O40: 0 | P40: 0 | Q40: 0 | R40: 0 | S40: 0 | T40: 0 | U40: =SUM('Debit Summary'!A40:G40) -> 0 | W40: PURE | X40: 8XN5908 | Y40: KIOXIA CORPORATION C/O KIOXIA AMERICA INC | Z40: 75.866526 | AA40: 100 | AB40: Victoria charge $100 to customer
...

Sheet Debit Summary
A1: Của sheet Logistics Record | S1: FedEx | T1: VVMV | U1: Dolphin | V1: EI | W1: DHL
A2: FedEx | B2: VVMV | C2: Dolphin | D2: EI | E2: Gia Bảo | F2: Evergreen | G2: DHL | T2: =COUNTIFS(VVMV!F:F,"raw materials",VVMV!N:N,"Air",VVMV!L:L,">0") -> 2 | U2: =COUNTIFS(Dolphin!H:H,"Air",Dolphin!G:G,"Raw materials") -> 0 | V2: =COUNTIFS(EI!F:F,"air import",EI!AY:AY,"Raw materials") -> 5
T3: =SUMIFS(VVMV!T:T,VVMV!F:F,"Raw materials",VVMV!N:N,"Air",VVMV!L:L,">0") -> 501 | U3: =SUMIFS(Dolphin!K:K,Dolphin!H:H,"Air",Dolphin!G:G,"Raw materials") -> 0 | V3: =SUMIFS(EI!M:M,EI!F:F,"air import",EI!AY:AY,"Raw materials") -> 594
I4: Double check | T4: =SUMIFS(VVMV!L:L,VVMV!F:F,"Raw materials",VVMV!N:N,"Air",VVMV!L:L,">0") -> 927.25482 | U4: ='FWD Detail'!BV50 -> 0 | V4: =SUMIFS(EI!AV:AV,EI!F:F,"air import",EI!AY:AY,"Raw materials") -> 1435.3751 | W4: =SUMIFS(EI!AW:AW,EI!G:G,"air import",EI!AZ:AZ,"Raw materials") -> 0
J5: fedex | K5: Ei | L5: dolphin | M5: vvmv | N5: DHL | O5: Evergreen | P5: Gia Bảo | Q5: Total | S5: =COUNTIF('FedEx Import'!S:S,"raw materials") -> 138
A6: =SUMIF('FedEx Import'!S:S,"Raw materials",'FedEx Import'!R:R) -> 9743.2527 | B6: =SUMIFS(VVMV!L:L,VVMV!E:E,"Import",VVMV!F:F,"Raw materials") -> 7975.643 | C6: =(SUMIF(Dolphin!G:G,"Raw materials",Dolphin!Q:Q)+SUMIF(Dolphin!G:G,"Raw materials",Dolphin!R:R)+SUMIF(Dolphin!G:G,"Raw materials",Dolphin!S:S)+SUMIF(Dolphin!G:G,"Raw materials",Dolphin!W:W))/'Logistics record '!AD1 -> 1899.1301 | D6: =SUMIFS(EI!AV:AV,EI!AX:AX,"import",EI!AY:AY,"Raw materials") -> 1435.3751 | G6: =SUMIF(DHL!C:C,"raw materials",DHL!W:W) -> 2103.8266 | I6: Xuất | J6: =SUM('FedEx Export'!AC:AC) -> 584.86641 | M6: =SUMIF(VVMV!E:E,"Export",VVMV!O:O) -> 818.15433 | N6: =SUMIF(DHL!B:B,"Export",DHL!W:W) -> 112.95749 | O6: =9000000/'Logistics record '!AD1 -> 340.11035 | Q6: =SUM(J6:P6) -> 1856.0886 | S6: =SUMIF('FedEx Import'!S:S,"raw materials",'FedEx Import'!L:L) -> 2534.8
A7: =COUNTIF('FedEx Import'!S:S,"raw materials") -> 138 | B7: =COUNTIFS(VVMV!F:F,"Raw materials",VVMV!L:L,">0") -> 14 | C7: =COUNTIF(Dolphin!G:G,"Raw materials") -> 4 | D7: =COUNTIF(EI!AY:AY,"Raw materials") -> 5 | G7: =COUNTIF(DHL!C:C,"Raw materials") -> 10 | J7: =J6*'Logistics record '!$AD$1 -> 15476735 | M7: =M6*'Logistics record '!$AD$1 -> 21650000 | S7: =SUMIF('FedEx Import'!S:S,"raw materials",'FedEx Import'!R:R) -> 9743.2527
A8: =SUMIF('FedEx Import'!S:S,"Raw materials",'FedEx Import'!L:L) -> 2534.8 | B8: =SUMIFS(VVMV!T:T,VVMV!F:F,"Raw materials",VVMV!L:L,">0") -> 9551.971 | C8: =SUMIF(Dolphin!G:G,"Raw materials",Dolphin!K:K) -> 2829.1 | D8: =SUMIF(EI!AY:AY,"Raw materials",EI!N:N) -> 586 | G8: =SUMIF(DHL!C:C,"Raw materials",DHL!O:O) -> 180 | I8: Nhập | J8: =SUM('FedEx Import'!R:R) -> 9743.2527 | K8: =SUM(EI!AV:AV) -> 2104.7273 | L8: =SUM(Dolphin!Y18:Y21)/'Logistics record '!$AD$1 -> 2192.3808 | M8: =SUMIF(VVMV!E:E,"import",VVMV!O:O) -> 25995.065 | N8: =SUMIF(DHL!B:B,"import",DHL!W:W) -> 2103.8266 | P8: =22000000/'Logistics record '!AD1 -> 831.38085 | Q8: =SUM(J8:P8) -> 42970.633 | W8: =COUNTIF(DHL!C:C,"Raw materials") -> 10
B9: =SUMIFS(VVMV!J:J,VVMV!E:E,"import",VVMV!F:F,"Raw materials")+SUMIFS(VVMV!K:K,VVMV!E:E,"import",VVMV!F:F,"Raw materials")+SUMIFS(VVMV!M:M,VVMV!E:E,"import",VVMV!F:F,"Raw materials") -> 17411.003 | C9: =SUMIF(Dolphin!G:G,"Raw materials",Dolphin!M:M)/'Logistics record '!AD1+SUMIF(Dolphin!G:G,"Raw materials",Dolphin!N:N)/'Logistics record '!AD1+SUMIF(Dolphin!G:G,"Raw materials",Dolphin!O:O)/'Logistics record '!AD1+SUMIF(Dolphin!G:G,"Raw materials",Dolphin!P:P)/'Logistics record '!AD1 -> 293.2507 | J9: =J8*'Logistics record '!$AD$1 -> 2.5782595e+08 | K9: =EI!AT23 -> 55570168 | L9: =L8*'Logistics record '!$AD$1 -> 58014781 | M9: =M8*'Logistics record '!$AD$1 -> 6.8788141e+08 | W9: =SUMIF(DHL!C:C,"raw materials",DHL!O:O) -> 180
B10: =COUNTIFS(VVMV!F:F,"raw materials",VVMV!J:J,">0") -> 527 | C10: 4 | I10: LPHQ | L10: =Dolphin!X22/'Logistics record '!$AD$1 -> 2.2674023 | M10: =SUMIF(VVMV!B:B,"Lệ phí hải quan",VVMV!AG:AG)/'Logistics record '!$AD$1 -> 232.40874 | Q10: =SUM(J10:P10) -> 234.67614 | W10: =SUMIF(DHL!C:C,"raw materials",DHL!W:W) -> 2103.8266
L11: =L10*'Logistics record '!$AD$1 -> 60000 | M11: =M10*'Logistics record '!$AD$1 -> 6150000 | Q11: =SUM(J11:P11) -> 6210000 | T11: =COUNTIFS(VVMV!F:F,"raw materials",VVMV!N:N,"Sea",VVMV!L:L,">0") -> 12 | U11: =COUNTIFS(Dolphin!H:H,"Sea",Dolphin!G:G,"Raw materials") -> 4 | V11: =COUNTIF(EI!F:F,"sea import") -> 0 | W11: =COUNTIF(EI!G:G,"sea import") -> 0
A12: =SUMIF('FedEx Import'!S:S,"Equipments + toolings",'FedEx Import'!R:R) -> 0 | B12: =SUMIFS(VVMV!L:L,VVMV!E:E,"Import",VVMV!F:F,"Equipments + Toolings") -> 0 | C12: =SUMIFS(Dolphin!AD:AD,Dolphin!AB:AB,"import",Dolphin!G:G,"Equipments + Toolings") -> 0 | D12: =SUMIFS(EI!AV:AV,EI!AX:AX,"import",EI!AY:AY,"equipments + toolings") -> 669.35217 | I12: BCQT | L12: =Dolphin!X24/'Logistics record '!$AD$1 -> 0 | M12: =SUMIF(VVMV!B:B,"Báo cáo quyết toán",VVMV!AG:AG)/'Logistics record '!$AD$1 -> 0 | Q12: =SUM(J12:P12) -> 0
A13: =SUMIF('FedEx Import'!S:S,"equipments + toolings",'FedEx Import'!L:L) -> 0 | B13: =SUMIFS(VVMV!T:T,VVMV!F:F,"Equipments + toolings",VVMV!L:L,">0") -> 0 | C13: =SUMIF(Dolphin!G18:G23,"Equipments + Toolings",Dolphin!K18:K23) -> 0 | D13: =SUMIF(EI!AY:AY,"Equipments + Toolings",EI!N:N) -> 288 | L13: =L12*'Logistics record '!$AD$1 -> 0 | M13: =M12*'Logistics record '!$AD$1 -> 0 | Q13: =SUM(J13:P13) -> 0 | T13: =SUMIFS(VVMV!L:L,VVMV!F:F,"Raw materials",VVMV!N:N,"Sea",VVMV!L:L,">0") -> 7048.3882 | U13: =SUMIFS(Dolphin!AD:AD,Dolphin!H:H,"sea",Dolphin!G:G,"Raw Materials") -> 1477.4045 | V13: =SUMIF(EI!F:F,"sea import",EI!AV:AV) -> 0 | W13: =SUMIF(EI!G:G,"sea import",EI!AW:AW) -> 0
B14: =SUMIFS(VVMV!J:J,VVMV!E:E,"import",VVMV!F:F,"Equipments + Toolings")+SUMIFS(VVMV!K:K,VVMV!E:E,"import",VVMV!F:F,"Equipments + Toolings")+SUMIFS(VVMV!M:M,VVMV!E:E,"import",VVMV!F:F,"Equipments + Toolings") -> 608.41933 | C14: =SUMIF(Dolphin!G:G,"Equipments + Toolings",Dolphin!M:M)/'Logistics record '!AD1+SUMIF(Dolphin!G:G,"Equipments + Toolings",Dolphin!N:N)/'Logistics record '!AD1+SUMIF(Dolphin!G:G,"Equipments + Toolings",Dolphin!O:O)/'Logistics record '!AD1+SUMIF(Dolphin!G:G,"Equipments + Toolings",Dolphin!P:P)/'Logistics record '!AD1 -> 0 | I14: Total | J14: =+J8+J6+J11 -> 10328.119 | K14: =+K8+K6+K11 -> 2104.7273 | L14: =L10+L8+L6 -> 2194.6482 | M14: =M10+M8+M6+M12 -> 27045.628 | N14: =N10+N8+N6+N12 -> 2216.784 | O14: =O10+O8+O6+O12 -> 340.11035 | P14: =P10+P8+P6+P12 -> 831.38085 | Q14: =SUM(J14:P14) -> 45061.398 | T14: =COUNTIF(VVMV!F:F,"raw materials") -> 527 | U14: =COUNTIF(Dolphin!G:G,"raw materials") -> 4
I15: VND | J15: =+J14*'Logistics record '!AD1 -> 2.7330269e+08 | K15: =SUM(EI!AU13:AU82) -> 55570168 | L15: =+L14*'Logistics record '!AD1 -> 58074781 | M15: =+M14*'Logistics record '!$AD$1 -> 7.1568141e+08 | N15: =+N14*'Logistics record '!$AD$1 -> 58660539 | O15: =+O14*'Logistics record '!$AD$1 -> 9000000 | P15: =P14*'Logistics record '!AD1 -> 22000000 | Q15: =+Q14*'Logistics record '!AD1 -> 1.1924147e+09 | T15: =SUMIF(VVMV!F:F,"raw materials",VVMV!J:J) -> 7932.1291 | U15: =SUMIF(Dolphin!G:G,"raw materials",Dolphin!AF:AF) -> 81.626483
E16: =22000000/'Logistics record '!AD1 -> 831.38085 | T16: =COUNTIFS(VVMV!F:F,"raw materials",VVMV!K:K,">0") -> 17 | U16: =COUNTIF(Dolphin!G:G,"raw materials") -> 4
T17: =SUMIF(VVMV!F:F,"raw materials",VVMV!K:K) -> 967.42499 | U17: =SUMIF(Dolphin!G:G,"raw materials",Dolphin!AG:AG) -> 211.62422
A18: =SUMIF('FedEx Export'!W:W,"transfer",'FedEx Export'!AC:AC) -> 354.56802 | C18: =(SUMIFS(Dolphin!Q:Q,Dolphin!AB:AB,"Export",Dolphin!AA:AA,"Transfer")+SUMIFS(Dolphin!R:R,Dolphin!AB:AB,"Export",Dolphin!AA:AA,"Transfer")+SUMIFS(Dolphin!S:S,Dolphin!AB:AB,"Export",Dolphin!AA:AA,"Transfer")+SUMIFS(Dolphin!X:X,Dolphin!AB:AB,"Export",Dolphin!AA:AA,"Transfer"))/'Logistics record '!$AD$1 -> 0 | T18: =COUNTIFS(VVMV!F:F,"raw materials",VVMV!M:M,">0") -> 142 | U18: =COUNTIF(Dolphin!G:G,"raw materials") -> 4
A19: =SUMIF('FedEx Export'!W:W,"transfer",'FedEx Export'!L:L) -> 27 | T19: =SUMIF(VVMV!F:F,"Raw materials",VVMV!M:M) -> 8511.4486 | U19: =SUMIF(Dolphin!G:G,"raw materials",Dolphin!AI:AI) -> 421.72557
B20: =SUMIFS(VVMV!O:O,VVMV!G:G,"Transfer",VVMV!E:E,"EXPORT") -> 239.96674 | C20: =(SUMIFS(Dolphin!M:M,Dolphin!AB:AB,"Export",Dolphin!AA:AA,"Transfer")+SUMIFS(Dolphin!N:N,Dolphin!AB:AB,"Export",Dolphin!AA:AA,"Transfer")+SUMIFS(Dolphin!O:O,Dolphin!AB:AB,"Export",Dolphin!AA:AA,"Transfer")+SUMIFS(Dolphin!P:P,Dolphin!AB:AB,"Export",Dolphin!AA:AA,"Transfer"))/'Logistics record '!$AD$1 -> 0 | S20: =SUMIF('Import material detail'!$C$2:$C$19,"Amount",S2:S19) -> 9743.2527 | T20: =SUMIF('Import material detail'!$C$2:$C$19,"Amount",T2:T19) -> 25386.646 | U20: =SUMIF('Import material detail'!$C$2:$C$19,"Amount",U2:U19) -> 2192.3808 | V20: =SUMIF('Import material detail'!$C$2:$C$19,"Amount",V2:V19) -> 1435.3751 | W20: =SUMIF('Import material detail'!$C$2:$C$19,"Amount",W2:W19) -> 2103.8266
S21: Của sheet Import material detail
A22: =SUMIF('FedEx Export'!W:W,"Lucid",'FedEx Export'!AC:AC) -> 0 | C22: =(SUMIFS(Dolphin!Q:Q,Dolphin!AB:AB,"Export",Dolphin!AA:AA,"Lucid")+SUMIFS(Dolphin!R:R,Dolphin!AB:AB,"Export",Dolphin!AA:AA,"Lucid")+SUMIFS(Dolphin!S:S,Dolphin!AB:AB,"Export",Dolphin!AA:AA,"Lucid")+SUMIFS(Dolphin!X:X,Dolphin!AB:AB,"Export",Dolphin!AA:AA,"Lucid"))/'Logistics record '!$AD$1 -> 0 | D22: =SUMIFS(EI!AV:AV,EI!AW:AW,"Lucid",EI!AX:AX,"Export") -> 0
A23: =SUMIF('FedEx Export'!W:W,"Lucid",'FedEx Export'!L:L) -> 0
B24: =SUMIFS(VVMV!O:O,VVMV!G:G,"Lucid",VVMV!E:E,"EXPORT") -> 211.62422 | C24: =(SUMIFS(Dolphin!M:M,Dolphin!AB:AB,"Export",Dolphin!AA:AA,"Lucid")+SUMIFS(Dolphin!N:N,Dolphin!AB:AB,"Export",Dolphin!AA:AA,"Lucid")+SUMIFS(Dolphin!O:O,Dolphin!AB:AB,"Export",Dolphin!AA:AA,"Lucid")+SUMIFS(Dolphin!P:P,Dolphin!AB:AB,"Export",Dolphin!AA:AA,"Lucid"))/'Logistics record '!$AD$1 -> 0
C26: =(SUMIFS(Dolphin!Q:Q,Dolphin!AB:AB,"Export",Dolphin!AA:AA,"Agiga")+SUMIFS(Dolphin!R:R,Dolphin!AB:AB,"Export",Dolphin!AA:AA,"Agiga")+SUMIFS(Dolphin!S:S,Dolphin!AB:AB,"Export",Dolphin!AA:AA,"Agiga")+SUMIFS(Dolphin!X:X,Dolphin!AB:AB,"Export",Dolphin!AA:AA,"Agiga"))/'Logistics record '!$AD$1 -> 0
C28: =(SUMIFS(Dolphin!M:M,Dolphin!AB:AB,"Export",Dolphin!AA:AA,"AGIGA")+SUMIFS(Dolphin!N:N,Dolphin!AB:AB,"Export",Dolphin!AA:AA,"AGIGA")+SUMIFS(Dolphin!O:O,Dolphin!AB:AB,"Export",Dolphin!AA:AA,"AGIGA")+SUMIFS(Dolphin!P:P,Dolphin!AB:AB,"Export",Dolphin!AA:AA,"AGIGA"))/'Logistics record '!$AD$1 -> 0
A30: =SUMIF('FedEx Export'!W:W,"EFI",'FedEx Export'!AC:AC) -> 0 | C30: =(SUMIFS(Dolphin!Q:Q,Dolphin!AB:AB,"Export",Dolphin!AA:AA,"EFI")+SUMIFS(Dolphin!R:R,Dolphin!AB:AB,"Export",Dolphin!AA:AA,"EFI")+SUMIFS(Dolphin!S:S,Dolphin!AB:AB,"Export",Dolphin!AA:AA,"EFI")+SUMIFS(Dolphin!X:X,Dolphin!AB:AB,"Export",Dolphin!AA:AA,"EFI"))/'Logistics record '!$AD$1 -> 0 | D30: =SUMIFS(EI!AV:AV,EI!AW:AW,"EFI",EI!AX:AX,"Export") -> 0
A31: =SUMIF('FedEx Export'!W:W,"EFI",'FedEx Export'!L:L) -> 0
B32: =SUMIFS(VVMV!O:O,VVMV!G:G,"EFI",VVMV!E:E,"EXPORT") -> 90.696093
C33: =(SUMIFS(Dolphin!M:M,Dolphin!AB:AB,"Export",Dolphin!AA:AA,"EFI")+SUMIFS(Dolphin!N:N,Dolphin!AB:AB,"Export",Dolphin!AA:AA,"EFI")+SUMIFS(Dolphin!O:O,Dolphin!AB:AB,"Export",Dolphin!AA:AA,"EFI")+SUMIFS(Dolphin!P:P,Dolphin!AB:AB,"Export",Dolphin!AA:AA,"EFI"))/'Logistics record '!$AD$1 -> 0
A35: =SUMIF('FedEx Export'!W:W,"Pure",'FedEx Export'!AC:AC) -> 79.008767 | C35: =(SUMIFS(Dolphin!Q:Q,Dolphin!AB:AB,"Export",Dolphin!AA:AA,"PURE")+SUMIFS(Dolphin!R:R,Dolphin!AB:AB,"Export",Dolphin!AA:AA,"PURE")+SUMIFS(Dolphin!S:S,Dolphin!AB:AB,"Export",Dolphin!AA:AA,"PURE")+SUMIFS(Dolphin!X:X,Dolphin!AB:AB,"Export",Dolphin!AA:AA,"PURE"))/'Logistics record '!$AD$1 -> 0 | D35: =SUMIFS(EI!AV:AV,EI!AW:AW,"PURE",EI!AX:AX,"Export") -> 0
A36: =SUMIF('FedEx Export'!W:W,"Pure",'FedEx Export'!L:L) -> 2.3
B37: =SUMIFS(VVMV!O:O,VVMV!G:G,"Pure",VVMV!E:E,"EXPORT") -> 213.51372 | C37: =(SUMIFS(Dolphin!M:M,Dolphin!AB:AB,"Export",Dolphin!AA:AA,"PURE")+SUMIFS(Dolphin!N:N,Dolphin!AB:AB,"Export",Dolphin!AA:AA,"PURE")+SUMIFS(Dolphin!O:O,Dolphin!AB:AB,"Export",Dolphin!AA:AA,"PURE")+SUMIFS(Dolphin!P:P,Dolphin!AB:AB,"Export",Dolphin!AA:AA,"PURE"))/'Logistics record '!$AD$1 -> 0
A39: =SUMIF('FedEx Export'!W:W,"AIC",'FedEx Export'!AC:AC) -> 0 | C39: =(SUMIFS(Dolphin!Q:Q,Dolphin!AB:AB,"Export",Dolphin!AA:AA,"AIC")+SUMIFS(Dolphin!R:R,Dolphin!AB:AB,"Export",Dolphin!AA:AA,"AIC")+SUMIFS(Dolphin!S:S,Dolphin!AB:AB,"Export",Dolphin!AA:AA,"AIC")+SUMIFS(Dolphin!X:X,Dolphin!AB:AB,"Export",Dolphin!AA:AA,"AIC"))/'Logistics record '!$AD$1 -> 0 | D39: =SUMIFS(EI!AV:AV,EI!AW:AW,"AIC",EI!AX:AX,"Export") -> 0
A40: =SUMIF('FedEx Export'!W:W,"AIC",'FedEx Export'!L:L) -> 0
B41: =SUMIFS(VVMV!O:O,VVMV!G:G,"AIC",VVMV!E:E,"EXPORT") -> 15.116015 | C41: =(SUMIFS(Dolphin!M:M,Dolphin!AB:AB,"Export",Dolphin!AA:AA,"AIC")+SUMIFS(Dolphin!N:N,Dolphin!AB:AB,"Export",Dolphin!AA:AA,"AIC")+SUMIFS(Dolphin!O:O,Dolphin!AB:AB,"Export",Dolphin!AA:AA,"AIC")+SUMIFS(Dolphin!P:P,Dolphin!AB:AB,"Export",Dolphin!AA:AA,"AIC"))/'Logistics record '!$AD$1 -> 0 | F41: =9000000/'Logistics record '!AD1 -> 340.11035
A43: =SUMIF('FedEx Export'!W:W,"Ford",'FedEx Export'!AC:AC) -> 0 | C43: =(SUMIFS(Dolphin!Q:Q,Dolphin!AB:AB,"Export",Dolphin!AA:AA,"Ford")+SUMIFS(Dolphin!R:R,Dolphin!AB:AB,"Export",Dolphin!AA:AA,"Ford")+SUMIFS(Dolphin!S:S,Dolphin!AB:AB,"Export",Dolphin!AA:AA,"Ford")+SUMIFS(Dolphin!X:X,Dolphin!AB:AB,"Export",Dolphin!AA:AA,"Ford"))/'Logistics record '!$AD$1 -> 0 | D43: =SUMIFS(EI!AV:AV,EI!AW:AW,"Ford",EI!AX:AX,"Export") -> 0 | G43: =SUMIFS(DHL!W:W,DHL!B:B,"export",DHL!D:D,"ford") -> 112.95749
A44: =SUMIF('FedEx Export'!W:W,"AIC",'FedEx Export'!L:L) -> 0 | G44: =SUMIFS(DHL!O:O,DHL!B:B,"export",DHL!D:D,"ford") -> 3.5
B45: =SUMIFS(VVMV!O:O,VVMV!G:G,"Ford",VVMV!E:E,"EXPORT") -> 0 | C45: =(SUMIFS(Dolphin!M:M,Dolphin!AB:AB,"Export",Dolphin!AA:AA,"Ford")+SUMIFS(Dolphin!N:N,Dolphin!AB:AB,"Export",Dolphin!AA:AA,"Ford")+SUMIFS(Dolphin!O:O,Dolphin!AB:AB,"Export",Dolphin!AA:AA,"Ford")+SUMIFS(Dolphin!P:P,Dolphin!AB:AB,"Export",Dolphin!AA:AA,"Ford"))/'Logistics record '!$AD$1 -> 0
B47: =SUMIFS(VVMV!O:O,VVMV!G:G,"OEM",VVMV!E:E,"EXPORT")+SUMIFS(VVMV!O:O,VVMV!G:G,"Other",VVMV!E:E,"EXPORT")+SUMIFS(VVMV!O:O,VVMV!G:G,"AGIGA",VVMV!E:E,"EXPORT") -> 47.237548 | C47: =(SUMIFS(Dolphin!M:M,Dolphin!AB:AB,"Export",Dolphin!AA:AA,"OEM")+SUMIFS(Dolphin!N:N,Dolphin!AB:AB,"Export",Dolphin!AA:AA,"OEM")+SUMIFS(Dolphin!O:O,Dolphin!AB:AB,"Export",Dolphin!AA:AA,"OEM")+SUMIFS(Dolphin!P:P,Dolphin!AB:AB,"Export",Dolphin!AA:AA,"OEM"))/'Logistics record '!$AD$1+(SUMIFS(Dolphin!M:M,Dolphin!AB:AB,"Export",Dolphin!AA:AA,"OTHER")+SUMIFS(Dolphin!N:N,Dolphin!AB:AB,"Export",Dolphin!AA:AA,"OTHER")+SUMIFS(Dolphin!O:O,Dolphin!AB:AB,"Export",Dolphin!AA:AA,"OTHER")+SUMIFS(Dolphin!P:P,Dolphin!AB:AB,"Export",Dolphin!AA:AA,"OTHER"))/'Logistics record '!$AD$1 -> 0 | D47: =SUMIFS(EI!AV:AV,EI!AW:AW,"OEM",EI!AX:AX,"Export") -> 0
...

Sheet FedEx Export
R1: VLOOKUP
B2: VAT INVOICE NO. | C2: DEBIT NOTE NO. | D2: DEBIT NOTE DATE | E2: AWB | F2: SHIP DATE | G2: SHIPPER | H2: CONSIGNEE | I2: ORIG | J2: DEST | K2: SERV | L2: CHRGBL WGHT (KG) | M2: NET CHARGE | N2: OTHER CHARGE | O2: FUEL SURCHARGE | P2: VAT (8%) | Q2: TOTAL AMOUNT (VND) | R2: STT | S2: Description | T2: Invoice | U2: Remark | V2: Who pays? | W2: Route | X2: STT | Y2: GW | Z2: CONSIGNEE | AA2: DEST | AB2: Final Amount | AC2: USD | AD2: VVMV | AE2: TOTAL
B3: 1K26TFA-00029775 | C3: 734101624 | D3: 46199 | E3: 872009826743 | F3: 46162 | G3: UNIGEN VIET NAM HANOI CO., LTD | H3: AGIGA TECH (CHENGDU) LLC | I3: VN | J3: CN | K3: 2P | L3: 11.8 | M3: 1746034 | N3: 0 | O3: 851192 | P3: 207778 | Q3: 2805004 | R3: 344 | S3: CUPCAKE | T3: INV06818 | U3: Ship to CTU | V3: x | W3: OEM | X3: 344 | Y3: 8 | Z3: CTU | AA3: CN | AB3: 2805004 | AC3: =AB3/'Logistics record '!$AD$1 -> 106.00121 | AD3: =SUMIF(VVMV!F:F,'FedEx Export'!T3,VVMV!O:O) -> 0 | AE3: =AD3+AC3 -> 106.00121
B4: 1K26TFA-00029775 | C4: 734101624 | D4: 46199 | E4: 872266860800 | F4: 46169 | G4: UNIGEN VIET NAM HANOI CO., LTD | H4: PURE STORAGE, INC. | I4: VN | J4: US | K4: IE | L4: 0.6 | M4: 610238 | N4: 68300 | O4: 302068 | P4: 78448 | Q4: 1059054 | R4: 372 | S4: IC | T4: Sample 754 | U4: Ship QA's sample for evaluation | V4: x | W4: PURE | X4: 372 | Y4: 0.092 | Z4: PURE US | AA4: US | AB4: 1059054 | AC4: =AB4/'Logistics record '!$AD$1 -> 40.021691 | AD4: =SUMIF(VVMV!F:F,'FedEx Export'!T4,VVMV!O:O) -> 0 | AE4: =AD4+AC4 -> 40.021691
B5: 1K26TFA-00029775 | C5: 734101624 | D5: 46199 | E5: 872329335608 | F5: 46171 | G5: UNIGEN VIET NAM HANOI CO., LTD | H5: UNIGEN CORPORATION | I5: VN | J5: US | K5: IE | L5: 1.7 | M5: 814665 | N5: 68300 | O5: 403259 | P5: 102898 | Q5: 1389122 | R5: 390 | S5: PCBA, STEEL | T5: E01087 | U5: Transfer material | V5: x | W5: Transfer | X5: 390 | Y5: 1.1 | Z5: HQ1 | AA5: US | AB5: 1389122 | AC5: =AB5/'Logistics record '!$AD$1 -> 52.494974 | AD5: =SUMIF(VVMV!F:F,'FedEx Export'!T5,VVMV!O:O) -> 47.237548 | AE5: =AD5+AC5 -> 99.732522
B6: 1K26TFA-00029775 | C6: 734101624 | D6: 46199 | E6: 872639262181 | F6: 46178 | G6: UNIGEN VIET NAM HANOI CO., LTD | H6: UNIGEN CORPORATION | I6: VN | J6: US | K6: IE | L6: 16 | M6: 2797192 | N6: 68300 | O6: 1377617 | P6: 339449 | Q6: 4582558 | R6: 397 | S6: IC, RES, TRANS, DIODE, LABEL, CAP | T6: E01089 | U6: Transfer material | V6: x | W6: Transfer | X6: 397 | Y6: 8.9 | Z6: HQ1 | AA6: US | AB6: 4582558 | AC6: =AB6/'Logistics record '!$AD$1 -> 173.17504 | AD6: =SUMIF(VVMV!F:F,'FedEx Export'!T6,VVMV!O:O) -> 47.237548 | AE6: =AD6+AC6 -> 220.41259
B7: 1K26TFA-00029775 | C7: 734101624 | D7: 46199 | E7: 872758765274 | F7: 46181 | G7: UNIGEN VIET NAM HANOI CO., LTD | H7: COMPEQ MANUFACTURING (HUIZHOU) | I7: VN | J7: CN | K7: 2P | L7: 1.7 | M7: 670355 | N7: 0 | O7: 284901 | P7: 76420 | Q7: 1031676 | R7: 402 | S7: PCB | T7: Sample 756 | U7: Ship QA's sample for evaluation | V7: x | W7: PURE | X7: 402 | Y7: 1.653 | Z7: COMPEQ | AA7: CN | AB7: 1031676 | AC7: =AB7/'Logistics record '!$AD$1 -> 38.987076 | AD7: =SUMIF(VVMV!F:F,'FedEx Export'!T7,VVMV!O:O) -> 0 | AE7: =AD7+AC7 -> 38.987076
B8: 1K26TFA-00029775 | C8: 734101624 | D8: 46199 | E8: 872885278038 | F8: 46184 | G8: UNIGEN VIET NAM HANOI CO., LTD | H8: INGRASYS TECHNOLOGY INC. | I8: VN | J8: TW | K8: IE | L8: 4.6 | M8: 778702 | N8: 0 | O8: 330948 | P8: 88772 | Q8: 1198422 | R8: 410 | S8: DDR4 | T8: INV06869 | U8: RMA | V8: x | W8: OEM | X8: 410 | Y8: 1.6 | Z8: INGRASYS | AA8: TW | AB8: 1198422 | AC8: =AB8/'Logistics record '!$AD$1 -> 45.288414 | AD8: =SUMIF(VVMV!F:F,'FedEx Export'!T8,VVMV!O:O) -> 47.237548 | AE8: =AD8+AC8 -> 92.525962
B9: 1K26TFA-00029775 | C9: 734101624 | D9: 46199 | E9: 873056855970 | F9: 46188 | G9: UNIGEN VIET NAM HANOI CO., LTD | H9: UNIGEN CORPORATION | I9: VN | J9: US | K9: 2P | L9: 9.3 | M9: 2160797 | N9: 68300 | O9: 929143 | P9: 252659 | Q9: 3410899 | R9: 424 | S9: SSD | T9: INV06883 | U9: Transfer FG | V9: x | W9: Transfer | X9: 424 | Y9: 7 | Z9: HQ1 | AA9: US | AB9: 3410899 | AC9: =AB9/'Logistics record '!$AD$1 -> 128.898 | AD9: =SUMIF(VVMV!F:F,'FedEx Export'!T9,VVMV!O:O) -> 15.116015 | AE9: =AD9+AC9 -> 144.01402
AE10: =SUM(AC3:AC9) -> 584.86641
P12: Total in VND (Including VAT) | Q12: =SUM(Q3:Q9) -> 15476735
O13: =Q12/26367 -> 586.97368

Sheet FedEx Import
B1: VAT INVOICE NO. | C1: DEBIT NOTE NO. | D1: DEBIT NOTE DATE | E1: AWB | F1: SHIP DATE | G1: SHIPPER | H1: CONSIGNEE | I1: ORIG | J1: DEST | K1: SERV | L1: CHRGBL WGHT (KG) | M1: NET CHARGE | N1: OTHER CHARGE | O1: FUEL SURCHARGE | P1: VAT (5.26%) | Q1: TOTAL AMOUNT (VND) | R1: USD | S1: Type | T1: Who pays? | U1: Route | V1: VVMV customs fee | W1: TOTAL
B2: 1K26TFA-00029774 | C2: 734101623 | D2: 46199 | E2: 381335227154 | F2: 46160 | G2: DHL SUPPLY CHAIN MGMT PHILS. INC | H2: UNIGEN CORPORATION | I2: PH | J2: VN | K2: IE | L2: 0.8 | M2: 448955 | N2: 137374 | O2: 213254 | P2: 42058 | Q2: 841641 | R2: =Q2/'Logistics record '!$AD$1 -> 31.805646 | S2: Raw materials | U2: {=IFERROR( _xlfn.IFS( VLOOKUP(E2,[1]Material!F$5:U$90000,16,0)="LUC","Lucid", VLOOKUP(E2,[1]Material!F$5:U$90000,16,0)="FMC","FORD", OR(VLOOKUP(E2,[1]Material!F$5:U$90000,16,0)="PUR",VLOOKUP(E2,[1]Material!F$5:U$90000,16,0)="HLO"),"PURE", VLOOKUP(E2,[1]Material!F$5:U$90000,16,0)="AIC","AIC", OR(VLOOKUP(E2,[1]Material!F$5:U$90000,16,0)="AGI",VLOOKUP(E2,[1]Material!F$5:U$90000,16,0)="AGIGA"),"AGIGA", OR(LEFT(VLOOKUP(E2,[1]Material!F$5:U$90000,16,0),3)="EF-",VLOOKUP(E2,[1]Material!F$5:U$90000,16,0)="EFI"),"EFI", AND(ISNUMBER(VLOOKUP(E2,[1]Material!F$5:U$90000,16,0)),VLOOKUP(E2,[1]Material!F$5:U$90000,16,0)>=100,VLOOKUP(E2,[1]Material!F$5:U$90000,16,0)<=999,VLOOKUP(E2,[1]Material!F$5:U$90000,16,0)=INT(VLOOKUP(E2,[1]Material!F$5:U$90000,16,0))),"OEM", TRUE,"" ), "không tìm thấy trong file Import" )} -> EFI | V2: =IFERROR(_xlfn.XLOOKUP(E:E,VVMV!B:B,VVMV!J:J),0) -> 15.116015 | W2: =V2+R2 -> 46.921661
B3: 1K26TFA-00029774 | C3: 734101623 | D3: 46199 | E3: 381471618942 | F3: 46163 | G3: DHL SUPPLY CHAIN MGMT PHILS. INC | H3: UNIGEN CORPORATION | I3: PH | J3: VN | K3: IE | L3: 2.6 | M3: 633735 | N3: 136652 | O3: 308946 | P3: 56773 | Q3: 1136106 | R3: =Q3/'Logistics record '!$AD$1 -> 42.93349 | S3: Raw materials | U3: {=IFERROR( _xlfn.IFS( VLOOKUP(E3,[1]Material!F$5:U$90000,16,0)="LUC","Lucid", VLOOKUP(E3,[1]Material!F$5:U$90000,16,0)="FMC","FORD", OR(VLOOKUP(E3,[1]Material!F$5:U$90000,16,0)="PUR",VLOOKUP(E3,[1]Material!F$5:U$90000,16,0)="HLO"),"PURE", VLOOKUP(E3,[1]Material!F$5:U$90000,16,0)="AIC","AIC", OR(VLOOKUP(E3,[1]Material!F$5:U$90000,16,0)="AGI",VLOOKUP(E3,[1]Material!F$5:U$90000,16,0)="AGIGA"),"AGIGA", OR(LEFT(VLOOKUP(E3,[1]Material!F$5:U$90000,16,0),3)="EF-",VLOOKUP(E3,[1]Material!F$5:U$90000,16,0)="EFI"),"EFI", AND(ISNUMBER(VLOOKUP(E3,[1]Material!F$5:U$90000,16,0)),VLOOKUP(E3,[1]Material!F$5:U$90000,16,0)>=100,VLOOKUP(E3,[1]Material!F$5:U$90000,16,0)<=999,VLOOKUP(E3,[1]Material!F$5:U$90000,16,0)=INT(VLOOKUP(E3,[1]Material!F$5:U$90000,16,0))),"OEM", TRUE,"" ), "không tìm thấy trong file Import" )} -> PURE | V3: =IFERROR(_xlfn.XLOOKUP(E:E,VVMV!B:B,VVMV!J:J),0) -> 0 | W3: =V3+R3 -> 42.93349
B4: 1K26TFA-00029774 | C4: 734101623 | D4: 46199 | E4: 381501224770 | F4: 46164 | G4: DHL SUPPLY CHAIN MGMT PHILS. INC | H4: UNIGEN CORPORATION | I4: PH | J4: VN | K4: IE | L4: 6.3 | M4: 908289 | N4: 137068 | O4: 442791 | P4: 78277 | Q4: 1566425 | R4: =Q4/'Logistics record '!$AD$1 -> 59.195261 | S4: Raw materials | U4: {=IFERROR( _xlfn.IFS( VLOOKUP(E4,[1]Material!F$5:U$90000,16,0)="LUC","Lucid", VLOOKUP(E4,[1]Material!F$5:U$90000,16,0)="FMC","FORD", OR(VLOOKUP(E4,[1]Material!F$5:U$90000,16,0)="PUR",VLOOKUP(E4,[1]Material!F$5:U$90000,16,0)="HLO"),"PURE", VLOOKUP(E4,[1]Material!F$5:U$90000,16,0)="AIC","AIC", OR(VLOOKUP(E4,[1]Material!F$5:U$90000,16,0)="AGI",VLOOKUP(E4,[1]Material!F$5:U$90000,16,0)="AGIGA"),"AGIGA", OR(LEFT(VLOOKUP(E4,[1]Material!F$5:U$90000,16,0),3)="EF-",VLOOKUP(E4,[1]Material!F$5:U$90000,16,0)="EFI"),"EFI", AND(ISNUMBER(VLOOKUP(E4,[1]Material!F$5:U$90000,16,0)),VLOOKUP(E4,[1]Material!F$5:U$90000,16,0)>=100,VLOOKUP(E4,[1]Material!F$5:U$90000,16,0)<=999,VLOOKUP(E4,[1]Material!F$5:U$90000,16,0)=INT(VLOOKUP(E4,[1]Material!F$5:U$90000,16,0))),"OEM", TRUE,"" ), "không tìm thấy trong file Import" )} -> PURE | V4: =IFERROR(_xlfn.XLOOKUP(E:E,VVMV!B:B,VVMV!J:J),0) -> 15.116015 | W4: =V4+R4 -> 74.311277
B5: 1K26TFA-00029774 | C5: 734101623 | D5: 46199 | E5: 381600540944 | F5: 46169 | G5: DHL SUPPLY CHAIN MGMT PHILS. INC | H5: UNIGEN CORPORATION | I5: PH | J5: VN | K5: IE | L5: 5.4 | M5: 841155 | N5: 137496 | O5: 416372 | P5: 73378 | Q5: 1468401 | R5: =Q5/'Logistics record '!$AD$1 -> 55.49093 | S5: Raw materials | U5: {=IFERROR( _xlfn.IFS( VLOOKUP(E5,[1]Material!F$5:U$90000,16,0)="LUC","Lucid", VLOOKUP(E5,[1]Material!F$5:U$90000,16,0)="FMC","FORD", OR(VLOOKUP(E5,[1]Material!F$5:U$90000,16,0)="PUR",VLOOKUP(E5,[1]Material!F$5:U$90000,16,0)="HLO"),"PURE", VLOOKUP(E5,[1]Material!F$5:U$90000,16,0)="AIC","AIC", OR(VLOOKUP(E5,[1]Material!F$5:U$90000,16,0)="AGI",VLOOKUP(E5,[1]Material!F$5:U$90000,16,0)="AGIGA"),"AGIGA", OR(LEFT(VLOOKUP(E5,[1]Material!F$5:U$90000,16,0),3)="EF-",VLOOKUP(E5,[1]Material!F$5:U$90000,16,0)="EFI"),"EFI", AND(ISNUMBER(VLOOKUP(E5,[1]Material!F$5:U$90000,16,0)),VLOOKUP(E5,[1]Material!F$5:U$90000,16,0)>=100,VLOOKUP(E5,[1]Material!F$5:U$90000,16,0)<=999,VLOOKUP(E5,[1]Material!F$5:U$90000,16,0)=INT(VLOOKUP(E5,[1]Material!F$5:U$90000,16,0))),"OEM", TRUE,"" ), "không tìm thấy trong file Import" )} -> EFI | V5: =IFERROR(_xlfn.XLOOKUP(E:E,VVMV!B:B,VVMV!J:J),0) -> 15.116015 | W5: =V5+R5 -> 70.606946
B6: 1K26TFA-00029774 | C6: 734101623 | D6: 46199 | E6: 381633142753 | F6: 46170 | G6: DHL SUPPLY CHAIN MGMT PHILS. INC | H6: UNIGEN CORPORATION | I6: PH | J6: VN | K6: IE | L6: 2.6 | M6: 633735 | N6: 136969 | O6: 313699 | P6: 57040 | Q6: 1141443 | R6: =Q6/'Logistics record '!$AD$1 -> 43.135175 | S6: Raw materials | U6: {=IFERROR( _xlfn.IFS( VLOOKUP(E6,[1]Material!F$5:U$90000,16,0)="LUC","Lucid", VLOOKUP(E6,[1]Material!F$5:U$90000,16,0)="FMC","FORD", OR(VLOOKUP(E6,[1]Material!F$5:U$90000,16,0)="PUR",VLOOKUP(E6,[1]Material!F$5:U$90000,16,0)="HLO"),"PURE", VLOOKUP(E6,[1]Material!F$5:U$90000,16,0)="AIC","AIC", OR(VLOOKUP(E6,[1]Material!F$5:U$90000,16,0)="AGI",VLOOKUP(E6,[1]Material!F$5:U$90000,16,0)="AGIGA"),"AGIGA", OR(LEFT(VLOOKUP(E6,[1]Material!F$5:U$90000,16,0),3)="EF-",VLOOKUP(E6,[1]Material!F$5:U$90000,16,0)="EFI"),"EFI", AND(ISNUMBER(VLOOKUP(E6,[1]Material!F$5:U$90000,16,0)),VLOOKUP(E6,[1]Material!F$5:U$90000,16,0)>=100,VLOOKUP(E6,[1]Material!F$5:U$90000,16,0)<=999,VLOOKUP(E6,[1]Material!F$5:U$90000,16,0)=INT(VLOOKUP(E6,[1]Material!F$5:U$90000,16,0))),"OEM", TRUE,"" ), "không tìm thấy trong file Import" )} -> PURE | V6: =IFERROR(_xlfn.XLOOKUP(E:E,VVMV!B:B,VVMV!J:J),0) -> 15.116015 | W6: =V6+R6 -> 58.25119
B7: 1K26TFA-00029774 | C7: 734101623 | D7: 46199 | E7: 518337606988 | F7: 46170 | G7: MICROCHIP TECHNOLOGY OPS PHIL CORP | H7: UNIGEN VIETNAM HANOI CO LTD | I7: PH | J7: VN | K7: IE | L7: 29.7 | M7: 2509099 | N7: 138490 | O7: 1242004 | P7: 204593 | Q7: 4094186 | R7: =Q7/'Logistics record '!$AD$1 -> 154.71945 | S7: Raw materials | U7: {=IFERROR( _xlfn.IFS( VLOOKUP(E7,[1]Material!F$5:U$90000,16,0)="LUC","Lucid", VLOOKUP(E7,[1]Material!F$5:U$90000,16,0)="FMC","FORD", OR(VLOOKUP(E7,[1]Material!F$5:U$90000,16,0)="PUR",VLOOKUP(E7,[1]Material!F$5:U$90000,16,0)="HLO"),"PURE", VLOOKUP(E7,[1]Material!F$5:U$90000,16,0)="AIC","AIC", OR(VLOOKUP(E7,[1]Material!F$5:U$90000,16,0)="AGI",VLOOKUP(E7,[1]Material!F$5:U$90000,16,0)="AGIGA"),"AGIGA", OR(LEFT(VLOOKUP(E7,[1]Material!F$5:U$90000,16,0),3)="EF-",VLOOKUP(E7,[1]Material!F$5:U$90000,16,0)="EFI"),"EFI", AND(ISNUMBER(VLOOKUP(E7,[1]Material!F$5:U$90000,16,0)),VLOOKUP(E7,[1]Material!F$5:U$90000,16,0)>=100,VLOOKUP(E7,[1]Material!F$5:U$90000,16,0)<=999,VLOOKUP(E7,[1]Material!F$5:U$90000,16,0)=INT(VLOOKUP(E7,[1]Material!F$5:U$90000,16,0))),"OEM", TRUE,"" ), "không tìm thấy trong file Import" )} -> PURE | V7: =IFERROR(_xlfn.XLOOKUP(E:E,VVMV!B:B,VVMV!J:J),0) -> 15.116015 | W7: =V7+R7 -> 169.83546
B8: 1K26TFA-00029774 | C8: 734101623 | D8: 46199 | E8: 381794684335 | F8: 46177 | G8: DHL SUPPLY CHAIN MGMT PHILS. INC | H8: UNIGEN CORPORATION | I8: PH | J8: VN | K8: IE | L8: 8.8 | M8: 1076123 | N8: 136616 | O8: 529991 | P8: 91668 | Q8: 1834398 | R8: =Q8/'Logistics record '!$AD$1 -> 69.321971 | S8: Raw materials | U8: {=IFERROR( _xlfn.IFS( VLOOKUP(E8,[1]Material!F$5:U$90000,16,0)="LUC","Lucid", VLOOKUP(E8,[1]Material!F$5:U$90000,16,0)="FMC","FORD", OR(VLOOKUP(E8,[1]Material!F$5:U$90000,16,0)="PUR",VLOOKUP(E8,[1]Material!F$5:U$90000,16,0)="HLO"),"PURE", VLOOKUP(E8,[1]Material!F$5:U$90000,16,0)="AIC","AIC", OR(VLOOKUP(E8,[1]Material!F$5:U$90000,16,0)="AGI",VLOOKUP(E8,[1]Material!F$5:U$90000,16,0)="AGIGA"),"AGIGA", OR(LEFT(VLOOKUP(E8,[1]Material!F$5:U$90000,16,0),3)="EF-",VLOOKUP(E8,[1]Material!F$5:U$90000,16,0)="EFI"),"EFI", AND(ISNUMBER(VLOOKUP(E8,[1]Material!F$5:U$90000,16,0)),VLOOKUP(E8,[1]Material!F$5:U$90000,16,0)>=100,VLOOKUP(E8,[1]Material!F$5:U$90000,16,0)<=999,VLOOKUP(E8,[1]Material!F$5:U$90000,16,0)=INT(VLOOKUP(E8,[1]Material!F$5:U$90000,16,0))),"OEM", TRUE,"" ), "không tìm thấy trong file Import" )} -> PURE | V8: =IFERROR(_xlfn.XLOOKUP(E:E,VVMV!B:B,VVMV!J:J),0) -> 15.116015 | W8: =V8+R8 -> 84.437987
B9: 1K26TFA-00029774 | C9: 734101623 | D9: 46199 | E9: 381845821672 | F9: 46179 | G9: ANALOG DEVICES GEN. TRIAS, INC. | H9: UNIGEN CORPORATION | I9: PH | J9: VN | K9: IE | L9: 1.5 | M9: 495695 | N9: 136466 | O9: 244130 | P9: 46093 | Q9: 922384 | R9: =Q9/'Logistics record '!$AD$1 -> 34.856927 | S9: Raw materials | U9: {=IFERROR( _xlfn.IFS( VLOOKUP(E9,[1]Material!F$5:U$90000,16,0)="LUC","Lucid", VLOOKUP(E9,[1]Material!F$5:U$90000,16,0)="FMC","FORD", OR(VLOOKUP(E9,[1]Material!F$5:U$90000,16,0)="PUR",VLOOKUP(E9,[1]Material!F$5:U$90000,16,0)="HLO"),"PURE", VLOOKUP(E9,[1]Material!F$5:U$90000,16,0)="AIC","AIC", OR(VLOOKUP(E9,[1]Material!F$5:U$90000,16,0)="AGI",VLOOKUP(E9,[1]Material!F$5:U$90000,16,0)="AGIGA"),"AGIGA", OR(LEFT(VLOOKUP(E9,[1]Material!F$5:U$90000,16,0),3)="EF-",VLOOKUP(E9,[1]Material!F$5:U$90000,16,0)="EFI"),"EFI", AND(ISNUMBER(VLOOKUP(E9,[1]Material!F$5:U$90000,16,0)),VLOOKUP(E9,[1]Material!F$5:U$90000,16,0)>=100,VLOOKUP(E9,[1]Material!F$5:U$90000,16,0)<=999,VLOOKUP(E9,[1]Material!F$5:U$90000,16,0)=INT(VLOOKUP(E9,[1]Material!F$5:U$90000,16,0))),"OEM", TRUE,"" ), "không tìm thấy trong file Import" )} -> Lucid | V9: =IFERROR(_xlfn.XLOOKUP(E:E,VVMV!B:B,VVMV!J:J),0) -> 15.116015 | W9: =V9+R9 -> 49.972942
B10: 1K26TFA-00029774 | C10: 734101623 | D10: 46199 | E10: 518337618146 | F10: 46179 | G10: MICROCHIP TECHNOLOGY OPS PHIL CORP | H10: UNIGEN VIETNAM HANOI CO LTD | I10: PH | J10: VN | K10: IE | L10: 47.6 | M10: 3968419 | N10: 136466 | O10: 1954446 | P10: 318721 | Q10: 6378052 | R10: =Q10/'Logistics record '!$AD$1 -> 241.02683 | S10: Raw materials | U10: {=IFERROR( _xlfn.IFS( VLOOKUP(E10,[1]Material!F$5:U$90000,16,0)="LUC","Lucid", VLOOKUP(E10,[1]Material!F$5:U$90000,16,0)="FMC","FORD", OR(VLOOKUP(E10,[1]Material!F$5:U$90000,16,0)="PUR",VLOOKUP(E10,[1]Material!F$5:U$90000,16,0)="HLO"),"PURE", VLOOKUP(E10,[1]Material!F$5:U$90000,16,0)="AIC","AIC", OR(VLOOKUP(E10,[1]Material!F$5:U$90000,16,0)="AGI",VLOOKUP(E10,[1]Material!F$5:U$90000,16,0)="AGIGA"),"AGIGA", OR(LEFT(VLOOKUP(E10,[1]Material!F$5:U$90000,16,0),3)="EF-",VLOOKUP(E10,[1]Material!F$5:U$90000,16,0)="EFI"),"EFI", AND(ISNUMBER(VLOOKUP(E10,[1]Material!F$5:U$90000,16,0)),VLOOKUP(E10,[1]Material!F$5:U$90000,16,0)>=100,VLOOKUP(E10,[1]Material!F$5:U$90000,16,0)<=999,VLOOKUP(E10,[1]Material!F$5:U$90000,16,0)=INT(VLOOKUP(E10,[1]Material!F$5:U$90000,16,0))),"OEM", TRUE,"" ), "không tìm thấy trong file Import" )} -> PURE | V10: =IFERROR(_xlfn.XLOOKUP(E:E,VVMV!B:B,VVMV!J:J),0) -> 15.116015 | W10: =V10+R10 -> 256.14285
B11: 1K26TFA-00029774 | C11: 734101623 | D11: 46199 | E11: 382048162769 | F11: 46189 | G11: DHL SUPPLY CHAIN MGMT PHILS. INC | H11: UNIGEN CORPORATION | I11: PH | J11: VN | K11: IE | L11: 3 | M11: 633735 | N11: 139007 | O11: 272506 | P11: 54980 | Q11: 1100228 | R11: =Q11/'Logistics record '!$AD$1 -> 41.577659 | S11: Raw materials | U11: {=IFERROR( _xlfn.IFS( VLOOKUP(E11,[1]Material!F$5:U$90000,16,0)="LUC","Lucid", VLOOKUP(E11,[1]Material!F$5:U$90000,16,0)="FMC","FORD", OR(VLOOKUP(E11,[1]Material!F$5:U$90000,16,0)="PUR",VLOOKUP(E11,[1]Material!F$5:U$90000,16,0)="HLO"),"PURE", VLOOKUP(E11,[1]Material!F$5:U$90000,16,0)="AIC","AIC", OR(VLOOKUP(E11,[1]Material!F$5:U$90000,16,0)="AGI",VLOOKUP(E11,[1]Material!F$5:U$90000,16,0)="AGIGA"),"AGIGA", OR(LEFT(VLOOKUP(E11,[1]Material!F$5:U$90000,16,0),3)="EF-",VLOOKUP(E11,[1]Material!F$5:U$90000,16,0)="EFI"),"EFI", AND(ISNUMBER(VLOOKUP(E11,[1]Material!F$5:U$90000,16,0)),VLOOKUP(E11,[1]Material!F$5:U$90000,16,0)>=100,VLOOKUP(E11,[1]Material!F$5:U$90000,16,0)<=999,VLOOKUP(E11,[1]Material!F$5:U$90000,16,0)=INT(VLOOKUP(E11,[1]Material!F$5:U$90000,16,0))),"OEM", TRUE,"" ), "không tìm thấy trong file Import" )} -> PURE | V11: =IFERROR(_xlfn.XLOOKUP(E:E,VVMV!B:B,VVMV!J:J),0) -> 15.116015 | W11: =V11+R11 -> 56.693674
B12: 1K26TFA-00029774 | C12: 734101623 | D12: 46199 | E12: 873186448972 | F12: 46191 | G12: CYMMETRIK SHENZHEN PRINTING CO. LTD | H12: UNIGEN VIETNAM HANOI CO LTD | I12: CN | J12: VN | K12: 2P | L12: 2.4 | M12: 395415 | N12: 388350 | O12: 170028 | P12: 50170 | Q12: 1003963 | R12: =Q12/'Logistics record '!$AD$1 -> 37.9398 | S12: Raw materials | U12: {=IFERROR( _xlfn.IFS( VLOOKUP(E12,[1]Material!F$5:U$90000,16,0)="LUC","Lucid", VLOOKUP(E12,[1]Material!F$5:U$90000,16,0)="FMC","FORD", OR(VLOOKUP(E12,[1]Material!F$5:U$90000,16,0)="PUR",VLOOKUP(E12,[1]Material!F$5:U$90000,16,0)="HLO"),"PURE", VLOOKUP(E12,[1]Material!F$5:U$90000,16,0)="AIC","AIC", OR(VLOOKUP(E12,[1]Material!F$5:U$90000,16,0)="AGI",VLOOKUP(E12,[1]Material!F$5:U$90000,16,0)="AGIGA"),"AGIGA", OR(LEFT(VLOOKUP(E12,[1]Material!F$5:U$90000,16,0),3)="EF-",VLOOKUP(E12,[1]Material!F$5:U$90000,16,0)="EFI"),"EFI", AND(ISNUMBER(VLOOKUP(E12,[1]Material!F$5:U$90000,16,0)),VLOOKUP(E12,[1]Material!F$5:U$90000,16,0)>=100,VLOOKUP(E12,[1]Material!F$5:U$90000,16,0)<=999,VLOOKUP(E12,[1]Material!F$5:U$90000,16,0)=INT(VLOOKUP(E12,[1]Material!F$5:U$90000,16,0))),"OEM", TRUE,"" ), "không tìm thấy trong file Import" )} -> PURE | V12: =IFERROR(_xlfn.XLOOKUP(E:E,VVMV!B:B,VVMV!J:J),0) -> 15.116015 | W12: =V12+R12 -> 53.055816
B13: 1K26TFA-00029784 | C13: 734101625 | D13: 46199 | E13: 510007349877 | F13: 46150 | G13: SINO FAITH TECHNOLOGY DVPT LTD | H13: UNIGEN VIETNAM HANOI CO.LTD | I13: HK | J13: VN | K13: IE | L13: 3.8 | M13: 470100 | N13: 0 | O13: 212720 | P13: 35916 | Q13: 718736 | R13: =Q13/'Logistics record '!$AD$1 -> 27.161061 | S13: Raw materials | U13: {=IFERROR( _xlfn.IFS( VLOOKUP(E13,[1]Material!F$5:U$90000,16,0)="LUC","Lucid", VLOOKUP(E13,[1]Material!F$5:U$90000,16,0)="FMC","FORD", OR(VLOOKUP(E13,[1]Material!F$5:U$90000,16,0)="PUR",VLOOKUP(E13,[1]Material!F$5:U$90000,16,0)="HLO"),"PURE", VLOOKUP(E13,[1]Material!F$5:U$90000,16,0)="AIC","AIC", OR(VLOOKUP(E13,[1]Material!F$5:U$90000,16,0)="AGI",VLOOKUP(E13,[1]Material!F$5:U$90000,16,0)="AGIGA"),"AGIGA", OR(LEFT(VLOOKUP(E13,[1]Material!F$5:U$90000,16,0),3)="EF-",VLOOKUP(E13,[1]Material!F$5:U$90000,16,0)="EFI"),"EFI", AND(ISNUMBER(VLOOKUP(E13,[1]Material!F$5:U$90000,16,0)),VLOOKUP(E13,[1]Material!F$5:U$90000,16,0)>=100,VLOOKUP(E13,[1]Material!F$5:U$90000,16,0)<=999,VLOOKUP(E13,[1]Material!F$5:U$90000,16,0)=INT(VLOOKUP(E13,[1]Material!F$5:U$90000,16,0))),"OEM", TRUE,"" ), "không tìm thấy trong file Import" )} -> FORD | V13: =IFERROR(_xlfn.XLOOKUP(E:E,VVMV!B:B,VVMV!J:J),0) -> 0 | W13: =V13+R13 -> 27.161061
... B15: 1K26TFA-00029784 | C15: 734101625 | D15: 46199 | E15: 871633572370 | F15: 46154 | G15: CYMMETRIK SHENZHEN PRINTING CO. LTD | H15: UNIGEN VIETNAM HANOI CO LTD | I15: CN | J15: VN | K15: 2P | L15: 14.4 | M15: 1003834 | N15: 0 | O15: 476821 | P15: 77882 | Q15: 1558537 | R15: =Q15/'Logistics record '!$AD$1 -> 58.897173 | S15: Raw materials | U15: {=IFERROR( _xlfn.IFS( VLOOKUP(E15,[1]Material!F$5:U$90000,16,0)="LUC","Lucid", VLOOKUP(E15,[1]Material!F$5:U$90000,16,0)="FMC","FORD", OR(VLOOKUP(E15,[1]Material!F$5:U$90000,16,0)="PUR",VLOOKUP(E15,[1]Material!F$5:U$90000,16,0)="HLO"),"PURE", VLOOKUP(E15,[1]Material!F$5:U$90000,16,0)="AIC","AIC", OR(VLOOKUP(E15,[1]Material!F$5:U$90000,16,0)="AGI",VLOOKUP(E15,[1]Material!F$5:U$90000,16,0)="AGIGA"),"AGIGA", OR(LEFT(VLOOKUP(E15,[1]Material!F$5:U$90000,16,0),3)="EF-",VLOOKUP(E15,[1]Material!F$5:U$90000,16,0)="EFI"),"EFI", AND(ISNUMBER(VLOOKUP(E15,[1]Material!F$5:U$90000,16,0)),VLOOKUP(E15,[1]Material!F$5:U$90000,16,0)>=100,VLOOKUP(E15,[1]Material!F$5:U$90000,16,0)<=999,VLOOKUP(E15,[1]Material!F$5:U$90000,16,0)=INT(VLOOKUP(E15,[1]Material!F$5:U$90000,16,0))),"OEM", TRUE,"" ), "không tìm thấy trong file Import" )} -> PURE | V15: =IFERROR(_xlfn.XLOOKUP(E:E,VVMV!B:B,VVMV!J:J),0) -> 0 | W15: =V15+R15 -> 58.897173
B16: 1K26TFA-00029784 | C16: 734101625 | D16: 46199 | E16: 871686783285 | F16: 46154 | G16: UNIGEN SHENZHEN | H16: UNIGEN VIET NAM HA NOI CO.LTD | I16: CN | J16: VN | K16: 2P | L16: 0.5 | M16: 343361 | N16: 0 | O16: 163096 | P16: 26640 | Q16: 533097 | R16: =Q16/'Logistics record '!$AD$1 -> 20.145756 | S16: Raw materials | U16: OEM | V16: =IFERROR(_xlfn.XLOOKUP(E:E,VVMV!B:B,VVMV!J:J),0) -> 0 | W16: =V16+R16 -> 20.145756
B17: 1K26TFA-00029784 | C17: 734101625 | D17: 46199 | E17: 518027666436 | F17: 46155 | G17: MICROCHIP TECHNOLOGY (THAILAND). | H17: UNIGEN VIETNAM HANOI CO., LTD | I17: TH | J17: VN | K17: IE | L17: 17.6 | M17: 1120404 | N17: 0 | O17: 532192 | P17: 86927 | Q17: 1739523 | R17: =Q17/'Logistics record '!$AD$1 -> 65.736641 | S17: Raw materials | U17: {=IFERROR( _xlfn.IFS( VLOOKUP(E17,[1]Material!F$5:U$90000,16,0)="LUC","Lucid", VLOOKUP(E17,[1]Material!F$5:U$90000,16,0)="FMC","FORD", OR(VLOOKUP(E17,[1]Material!F$5:U$90000,16,0)="PUR",VLOOKUP(E17,[1]Material!F$5:U$90000,16,0)="HLO"),"PURE", VLOOKUP(E17,[1]Material!F$5:U$90000,16,0)="AIC","AIC", OR(VLOOKUP(E17,[1]Material!F$5:U$90000,16,0)="AGI",VLOOKUP(E17,[1]Material!F$5:U$90000,16,0)="AGIGA"),"AGIGA", OR(LEFT(VLOOKUP(E17,[1]Material!F$5:U$90000,16,0),3)="EF-",VLOOKUP(E17,[1]Material!F$5:U$90000,16,0)="EFI"),"EFI", AND(ISNUMBER(VLOOKUP(E17,[1]Material!F$5:U$90000,16,0)),VLOOKUP(E17,[1]Material!F$5:U$90000,16,0)>=100,VLOOKUP(E17,[1]Material!F$5:U$90000,16,0)<=999,VLOOKUP(E17,[1]Material!F$5:U$90000,16,0)=INT(VLOOKUP(E17,[1]Material!F$5:U$90000,16,0))),"OEM", TRUE,"" ), "không tìm thấy trong file Import" )} -> PURE | V17: =IFERROR(_xlfn.XLOOKUP(E:E,VVMV!B:B,VVMV!J:J),0) -> 0 | W17: =V17+R17 -> 65.736641
B18: 1K26TFA-00029784 | C18: 734101625 | D18: 46199 | E18: 871735931826 | F18: 46156 | G18: TONG LAY DOO INDUSTRIAL CO LTD. | H18: UNIGEN VIETNAM HANOI CO., LTD. | I18: TW | J18: VN | K18: IE | L18: 7.9 | M18: 749957 | N18: 0 | O18: 356230 | P18: 58185 | Q18: 1164372 | R18: =Q18/'Logistics record '!$AD$1 -> 44.001663 | S18: Raw materials | U18: {=IFERROR( _xlfn.IFS( VLOOKUP(E18,[1]Material!F$5:U$90000,16,0)="LUC","Lucid", VLOOKUP(E18,[1]Material!F$5:U$90000,16,0)="FMC","FORD", OR(VLOOKUP(E18,[1]Material!F$5:U$90000,16,0)="PUR",VLOOKUP(E18,[1]Material!F$5:U$90000,16,0)="HLO"),"PURE", VLOOKUP(E18,[1]Material!F$5:U$90000,16,0)="AIC","AIC", OR(VLOOKUP(E18,[1]Material!F$5:U$90000,16,0)="AGI",VLOOKUP(E18,[1]Material!F$5:U$90000,16,0)="AGIGA"),"AGIGA", OR(LEFT(VLOOKUP(E18,[1]Material!F$5:U$90000,16,0),3)="EF-",VLOOKUP(E18,[1]Material!F$5:U$90000,16,0)="EFI"),"EFI", AND(ISNUMBER(VLOOKUP(E18,[1]Material!F$5:U$90000,16,0)),VLOOKUP(E18,[1]Material!F$5:U$90000,16,0)>=100,VLOOKUP(E18,[1]Material!F$5:U$90000,16,0)<=999,VLOOKUP(E18,[1]Material!F$5:U$90000,16,0)=INT(VLOOKUP(E18,[1]Material!F$5:U$90000,16,0))),"OEM", TRUE,"" ), "không tìm thấy trong file Import" )} -> EFI | V18: =IFERROR(_xlfn.XLOOKUP(E:E,VVMV!B:B,VVMV!J:J),0) -> 15.116015 | W18: =V18+R18 -> 59.117678
